<?xml version="1.0" encoding="utf-8"?>
<!-- This URDF was automatically created by SolidWorks to URDF Exporter! Originally created by Stephen Brawner (brawner@gmail.com) 
     Commit Version: 1.6.0-4-g7f85cfe  Build Version: 1.6.7995.38578
     For more information, please see http://wiki.ros.org/sw_urdf_exporter -->
<robot
  name="RA605.SLDASM">
  <link
    name="base_link">
    <inertial>
      <origin
        xyz="-0.12853 -0.01705 0.068164"
        rpy="0 0 0" />
      <mass
        value="7.7086E-06" />
      <inertia
        ixx="3.6064E-12"
        ixy="-1.8252E-22"
        ixz="-1.3388E-13"
        iyy="4.1328E-12"
        iyz="-1.465E-21"
        izz="7.4357E-12" />
    </inertial>
    <visual>
      <origin
        xyz="0 0 0"
        rpy="0 0 0" />
      <geometry>
        <mesh
          filename="./meshes/base_link.STL" />
      </geometry>
      <material
        name="">
        <color
          rgba="1 0.8902 0.7098 1" />
      </material>
    </visual>
    <collision>
      <origin
        xyz="0 0 0"
        rpy="0 0 0" />
      <geometry>
        <mesh
          filename="./meshes/base_link.STL" />
      </geometry>
    </collision>
  </link>
  <link
    name="Link1">
    <inertial>
      <origin
        xyz="0.012604 -0.0042468 0.088586"
        rpy="0 0 0" />
      <mass
        value="2.7846" />
      <inertia
        ixx="0.012895"
        ixy="0.00020506"
        ixz="-0.0019527"
        iyy="0.013803"
        iyz="0.00072198"
        izz="0.0084823" />
    </inertial>
    <visual>
      <origin
        xyz="0 0 0"
        rpy="0 0 0" />
      <geometry>
        <mesh
          filename="./meshes/Link1.STL" />
      </geometry>
      <material
        name="">
        <color
          rgba="0.79216 0.81961 0.93333 1" />
      </material>
    </visual>
    <collision>
      <origin
        xyz="0 0 0"
        rpy="0 0 0" />
      <geometry>
        <mesh
          filename="./meshes/Link1.STL" />
      </geometry>
    </collision>
  </link>
  <joint
    name="Joint1"
    type="revolute">
    <origin
      xyz="-0.0045962 0 0.22398"
      rpy="0 -0.034907 0" />
    <parent
      link="base_link" />
    <child
      link="Link1" />
    <axis
      xyz="0 0 -1" />
    <limit
      lower="-2.8797933"
      upper="2.8797933"
      effort="100"
      velocity="1" />
  </joint>
  <link
    name="Link2">
    <inertial>
      <origin
        xyz="-0.0099321 0.15013 0.020425"
        rpy="0 0 0" />
      <mass
        value="7.6263" />
      <inertia
        ixx="0.14834"
        ixy="0.00059196"
        ixz="0.0004036"
        iyy="0.049968"
        iyz="-0.00065863"
        izz="0.11493" />
    </inertial>
    <visual>
      <origin
        xyz="0 0 0"
        rpy="0 0 0" />
      <geometry>
        <mesh
          filename="./meshes/Link2.STL" />
      </geometry>
      <material
        name="">
        <color
          rgba="0.79216 0.81961 0.93333 1" />
      </material>
    </visual>
    <collision>
      <origin
        xyz="0 0 0"
        rpy="0 0 0" />
      <geometry>
        <mesh
          filename="./meshes/Link2.STL" />
      </geometry>
    </collision>
  </link>
  <joint
    name="Joint2"
    type="revolute">
    <origin
      xyz="0.03 0.0383 0.151"
      rpy="1.5708 0 0" />
    <parent
      link="Link1" />
    <child
      link="Link2" />
    <axis
      xyz="0 0 -1" />
    <limit
      lower="-1.4835299"
      upper="2.1816616"
      effort="100"
      velocity="1" />
  </joint>
  <link
    name="Link3">
    <inertial>
      <origin
        xyz="0.0052575 0.019432 0.050623"
        rpy="0 0 0" />
      <mass
        value="2.3277" />
      <inertia
        ixx="0.0054056"
        ixy="-0.00094218"
        ixz="1.6547E-05"
        iyy="0.0078784"
        iyz="5.4039E-05"
        izz="0.0092192" />
    </inertial>
    <visual>
      <origin
        xyz="0 0 0"
        rpy="0 0 0" />
      <geometry>
        <mesh
          filename="./meshes/Link3.STL" />
      </geometry>
      <material
        name="">
        <color
          rgba="0.79216 0.81961 0.93333 1" />
      </material>
    </visual>
    <collision>
      <origin
        xyz="0 0 0"
        rpy="0 0 0" />
      <geometry>
        <mesh
          filename="./meshes/Link3.STL" />
      </geometry>
    </collision>
  </link>
  <joint
    name="Joint3"
    type="revolute">
    <origin
      xyz="0 0.34 -0.011"
      rpy="0 0 0" />
    <parent
      link="Link2" />
    <child
      link="Link3" />
    <axis
      xyz="0 0 1" />
    <limit
      lower="-0.95993109"
      upper="3.2288591"
      effort="100"
      velocity="1" />
  </joint>
  <link
    name="Link4">
    <inertial>
      <origin
        xyz="1.8166E-05 9.1138E-05 0.11394"
        rpy="0 0 0" />
      <mass
        value="3.0358" />
      <inertia
        ixx="0.018108"
        ixy="1.4547E-06"
        ixz="6.5679E-06"
        iyy="0.020248"
        iyz="6.2879E-06"
        izz="0.007326" />
    </inertial>
    <visual>
      <origin
        xyz="0 0 0"
        rpy="0 0 0" />
      <geometry>
        <mesh
          filename="./meshes/Link4.STL" />
      </geometry>
      <material
        name="">
        <color
          rgba="0.79216 0.81961 0.93333 1" />
      </material>
    </visual>
    <collision>
      <origin
        xyz="0 0 0"
        rpy="0 0 0" />
      <geometry>
        <mesh
          filename="./meshes/Link4.STL" />
      </geometry>
    </collision>
  </link>
  <joint
    name="Joint4"
    type="revolute">
    <origin
      xyz="0.099 0.04 0.0493"
      rpy="0 1.5708 0" />
    <parent
      link="Link3" />
    <child
      link="Link4" />
    <axis
      xyz="0 0 -1" />
    <limit
      lower="-3.3161256"
      upper="3.3161256"
      effort="100"
      velocity="1" />
  </joint>
  <link
    name="Link5">
    <inertial>
      <origin
        xyz="-1.2211E-06 -0.016723 -0.032472"
        rpy="0 0 0" />
      <mass
        value="0.43116" />
      <inertia
        ixx="0.00050781"
        ixy="-3.6444E-08"
        ixz="5.1464E-08"
        iyy="0.00029403"
        iyz="3.4359E-06"
        izz="0.00051675" />
    </inertial>
    <visual>
      <origin
        xyz="0 0 0"
        rpy="0 0 0" />
      <geometry>
        <mesh
          filename="./meshes/Link5.STL" />
      </geometry>
      <material
        name="">
        <color
          rgba="0.79216 0.81961 0.93333 1" />
      </material>
    </visual>
    <collision>
      <origin
        xyz="0 0 0"
        rpy="0 0 0" />
      <geometry>
        <mesh
          filename="./meshes/Link5.STL" />
      </geometry>
    </collision>
  </link>
  <joint
    name="Joint5"
    type="revolute">
    <origin
      xyz="-0.032 0 0.239"
      rpy="3.1416 -1.5708 3.1416" />
    <parent
      link="Link4" />
    <child
      link="Link5" />
    <axis
      xyz="0 0 -1" />
    <limit
      lower="-2.0071286"
      upper="2.0071286"
      effort="100"
      velocity="1" />
  </joint>
  <link
    name="Link6">
    <inertial>
      <origin
        xyz="-6.3046E-05 1.0946E-12 0.0093351"
        rpy="0 0 0" />
      <mass
        value="0.034935" />
      <inertia
        ixx="9.7338E-06"
        ixy="-1.0088E-15"
        ixz="1.328E-08"
        iyy="9.6985E-06"
        iyz="1.7295E-16"
        izz="1.815E-05" />
    </inertial>
    <visual>
      <origin
        xyz="0 0 0"
        rpy="0 0 0" />
      <geometry>
        <mesh
          filename="./meshes/Link6.STL" />
      </geometry>
      <material
        name="">
        <color
          rgba="0.7451 0.73725 0.72941 1" />
      </material>
    </visual>
    <collision>
      <origin
        xyz="0 0 0"
        rpy="0 0 0" />
      <geometry>
        <mesh
          filename="./meshes/Link6.STL" />
      </geometry>
    </collision>
  </link>
  <joint
    name="Joint6"
    type="revolute">
    <origin
      xyz="0 -0.0685 -0.032"
      rpy="1.5708 0 0" />
    <parent
      link="Link5" />
    <child
      link="Link6" />
    <axis
      xyz="0 0 -1" />
    <limit
      lower="-6.28"
      upper="6.28"
      effort="100"
      velocity="1" />
  </joint>

  <link name="ee">
    <inertial>
      <origin xyz="0 0 0" rpy="0 0 0"/>
      <mass value="0.001"/>
      <inertia ixx="1e-5" ixy="0" ixz="0" iyy="1e-5" iyz="0" izz="1e-5"/>
    </inertial>
    <visual>
      <origin xyz="0 0 0" rpy="0 0 0"/>
      <geometry>
        <!-- 將長、寬、高皆設為0.005公尺 (0.5cm) -->
        <box size="0.005 0.005 0.02"/>
      </geometry>
      <material name="">
        <color rgba="0 0 0.8 1"/>
      </material>
    </visual>
    <collision>
      <origin xyz="0 0 0" rpy="0 0 0"/>
      <geometry>
        <box size="0.005 0.005 0.02"/>
      </geometry>
    </collision>
  </link>
  <joint name="ee_joint" type="fixed">
    <origin xyz="0 0 0.02" rpy="0 0 0"/>
    <parent link="Link6"/>
    <child link="ee"/>
  </joint>

</robot>